{"name": "Подсветка поля при клике на иконку видимости", "status": "broken", "statusDetails": {"message": "ValueError: There is no such driver by url https://chromedriver.storage.googleapis.com/136.0.7103/chromedriver_win32.zip", "trace": "request = <SubRequest 'driver' for <Function test_navigate_to_restore_page>>\n\n    @pytest.fixture(scope=\"session\")\n    def driver(request):\n        browser = request.config.getoption(\"--browser\")\n        headless = request.config.getoption(\"--headless\")\n    \n        if browser == \"chrome\":\n            options = webdriver.ChromeOptions()\n            if headless:\n                options.add_argument(\"--headless=new\")\n>           service = ChromeService(executable_path=ChromeDriverManager().install())\n\ntests\\conftest.py:25: \n_ _ _ _ _ _ _ _ _ _ _ _ _ _ _ _ _ _ _ _ _ _ _ _ _ _ _ _ _ _ _ _ _ _ _ _ _ _ _ _ _ _ _ _ _ _ _ _ _ _ _ _ _ _ _ _ _ _ _ _ _ _ _ _ _ _ _ _ _ _ _ _ _ _ _ _ _ _ _ _ _ _ _\nvenv\\Lib\\site-packages\\webdriver_manager\\chrome.py:39: in install\n    driver_path = self._get_driver_path(self.driver)\nvenv\\Lib\\site-packages\\webdriver_manager\\core\\manager.py:30: in _get_driver_path\n    file = self._download_manager.download_file(driver.get_url())\nvenv\\Lib\\site-packages\\webdriver_manager\\core\\download_manager.py:28: in download_file\n    response = self._http_client.get(url)\nvenv\\Lib\\site-packages\\webdriver_manager\\core\\http.py:33: in get\n    self.validate_response(resp)\n_ _ _ _ _ _ _ _ _ _ _ _ _ _ _ _ _ _ _ _ _ _ _ _ _ _ _ _ _ _ _ _ _ _ _ _ _ _ _ _ _ _ _ _ _ _ _ _ _ _ _ _ _ _ _ _ _ _ _ _ _ _ _ _ _ _ _ _ _ _ _ _ _ _ _ _ _ _ _ _ _ _ _\n\nresp = <Response [404]>\n\n    @staticmethod\n    def validate_response(resp: requests.Response):\n        status_code = resp.status_code\n        if status_code == 404:\n>           raise ValueError(f\"There is no such driver by url {resp.url}\")\nE           ValueError: There is no such driver by url https://chromedriver.storage.googleapis.com/136.0.7103/chromedriver_win32.zip\n\nvenv\\Lib\\site-packages\\webdriver_manager\\core\\http.py:16: ValueError"}, "start": 1747161484338, "stop": 1747161484338, "uuid": "abbb9b6f-bd78-4f9d-ad6a-d154298931ea", "historyId": "8192bd2a5e0fd41d7b4ad7d376a19f71", "testCaseId": "55c275f4bd223f7c834a0991b2868f58", "fullName": "tests.test_password_restore.TestPasswordRestore#test_password_field_highlighting", "labels": [{"name": "feature", "value": "Восстановление пароля"}, {"name": "parentSuite", "value": "tests"}, {"name": "suite", "value": "test_password_restore"}, {"name": "subSuite", "value": "TestPasswordRestore"}, {"name": "host", "value": "Gemini_78"}, {"name": "thread", "value": "7780-MainThread"}, {"name": "framework", "value": "pytest"}, {"name": "language", "value": "cpython3"}, {"name": "package", "value": "tests.test_password_restore"}]}